[ 2023-04-14 12:49:24,042] 224 werkzeug - INFO - [31m[1mWARNING: This is a development server. Do not use it in a production deployment. Use a production WSGI server instead.[0m
 * Running on all addresses (0.0.0.0)
 * Running on http://127.0.0.1:5000
 * Running on http://192.168.41.61:5000
[ 2023-04-14 12:49:24,042] 224 werkzeug - INFO - [33mPress CTRL+C to quit[0m
[ 2023-04-14 12:58:33,679] 224 werkzeug - INFO - 127.0.0.1 - - [14/Apr/2023 12:58:33] "GET / HTTP/1.1" 200 -
[ 2023-04-14 12:58:33,864] 224 werkzeug - INFO - 127.0.0.1 - - [14/Apr/2023 12:58:33] "[33mGET /favicon.ico HTTP/1.1[0m" 404 -
[ 2023-04-14 12:59:10,526] 224 werkzeug - INFO - 127.0.0.1 - - [14/Apr/2023 12:59:10] "GET /predictdata HTTP/1.1" 200 -
[ 2023-04-14 12:59:33,989] 1744 app - ERROR - Exception on /predictdata [POST]
Traceback (most recent call last):
  File "E:\Github\ml_project\src\utils.py", line 57, in load_object
    with open(file_path, "rb") as file_obj:
FileNotFoundError: [Errno 2] No such file or directory: 'artifacts\\preprocessor.pkl'

During handling of the above exception, another exception occurred:

Traceback (most recent call last):
  File "E:\Github\ml_project\src\pipeline\predict_pipeline.py", line 16, in predict
    preprocessor=load_object(file_path=preprocessor_path)
  File "E:\Github\ml_project\src\utils.py", line 61, in load_object
    raise CustomException(e, sys)
src.exception.CustomException: Error Occured in python script name [E:\Github\ml_project\src\utils.py], in line number [57], error message [[Errno 2] No such file or directory: 'artifacts\\preprocessor.pkl']

During handling of the above exception, another exception occurred:

Traceback (most recent call last):
  File "e:\Github\ml_project\venv\lib\site-packages\flask\app.py", line 2528, in wsgi_app
    response = self.full_dispatch_request()
  File "e:\Github\ml_project\venv\lib\site-packages\flask\app.py", line 1825, in full_dispatch_request
    rv = self.handle_user_exception(e)
  File "e:\Github\ml_project\venv\lib\site-packages\flask\app.py", line 1823, in full_dispatch_request
    rv = self.dispatch_request()
  File "e:\Github\ml_project\venv\lib\site-packages\flask\app.py", line 1799, in dispatch_request
    return self.ensure_sync(self.view_functions[rule.endpoint])(**view_args)
  File "app.py", line 39, in predict_datapoint
    results=predict_pipeline.predict(pred_df)
  File "E:\Github\ml_project\src\pipeline\predict_pipeline.py", line 22, in predict
    raise CustomException(e,sys)
src.exception.CustomException: Error Occured in python script name [E:\Github\ml_project\src\pipeline\predict_pipeline.py], in line number [16], error message [Error Occured in python script name [E:\Github\ml_project\src\utils.py], in line number [57], error message [[Errno 2] No such file or directory: 'artifacts\\preprocessor.pkl']]
[ 2023-04-14 12:59:33,993] 224 werkzeug - INFO - 127.0.0.1 - - [14/Apr/2023 12:59:33] "[35m[1mPOST /predictdata HTTP/1.1[0m" 500 -
[ 2023-04-14 12:59:55,106] 1744 app - ERROR - Exception on /predictdata [POST]
Traceback (most recent call last):
  File "E:\Github\ml_project\src\utils.py", line 57, in load_object
    with open(file_path, "rb") as file_obj:
FileNotFoundError: [Errno 2] No such file or directory: 'artifacts\\preprocessor.pkl'

During handling of the above exception, another exception occurred:

Traceback (most recent call last):
  File "E:\Github\ml_project\src\pipeline\predict_pipeline.py", line 16, in predict
    preprocessor=load_object(file_path=preprocessor_path)
  File "E:\Github\ml_project\src\utils.py", line 61, in load_object
    raise CustomException(e, sys)
src.exception.CustomException: Error Occured in python script name [E:\Github\ml_project\src\utils.py], in line number [57], error message [[Errno 2] No such file or directory: 'artifacts\\preprocessor.pkl']

During handling of the above exception, another exception occurred:

Traceback (most recent call last):
  File "e:\Github\ml_project\venv\lib\site-packages\flask\app.py", line 2528, in wsgi_app
    response = self.full_dispatch_request()
  File "e:\Github\ml_project\venv\lib\site-packages\flask\app.py", line 1825, in full_dispatch_request
    rv = self.handle_user_exception(e)
  File "e:\Github\ml_project\venv\lib\site-packages\flask\app.py", line 1823, in full_dispatch_request
    rv = self.dispatch_request()
  File "e:\Github\ml_project\venv\lib\site-packages\flask\app.py", line 1799, in dispatch_request
    return self.ensure_sync(self.view_functions[rule.endpoint])(**view_args)
  File "app.py", line 39, in predict_datapoint
    results=predict_pipeline.predict(pred_df)
  File "E:\Github\ml_project\src\pipeline\predict_pipeline.py", line 22, in predict
    raise CustomException(e,sys)
src.exception.CustomException: Error Occured in python script name [E:\Github\ml_project\src\pipeline\predict_pipeline.py], in line number [16], error message [Error Occured in python script name [E:\Github\ml_project\src\utils.py], in line number [57], error message [[Errno 2] No such file or directory: 'artifacts\\preprocessor.pkl']]
[ 2023-04-14 12:59:55,110] 224 werkzeug - INFO - 127.0.0.1 - - [14/Apr/2023 12:59:55] "[35m[1mPOST /predictdata HTTP/1.1[0m" 500 -
